Workbook

Sheet SUMMARY
B2: S/N | C2: BP Catalog Number | D2: BP Catalog Description | E2: Item No. | F2: Item Description | G2: current PO price | H2: PRICE | I2: difference | J2: differentail
B3: 1 | C3: 919615893871 | D3: BRP277 LED180 CW M2 SLR PSU S2 | E3: 30302118 | F3: BRP277 S2 5.7K 150W | G3: 2007.05 | H3: ='BRP277 150 S2'!J58 -> 2284.1867 | I3: =H3-G3 -> 277.13668 | J3: =I3/G3 -> 0.1380816
B4: 2 | C4: 919615893872 | D4: BRP277 LED180 CW M2 SLR PSU SPD S2 | E4: 30302117 | F4: BRP277 S2 5.7K 150W SPD | G4: 2066.17 | H4: ='BRP277 150 SPD S2'!I59 -> #N/A | I4: =H4-G4 -> #N/A | J4: =I4/G4 -> #N/A
B5: 3 | C5: 919615893873 | D5: BRP277 LED195 CW M2 SLR PSU S3 | E5: 30302120 | F5: BRP277 S3 5.7K 150W | G5: 2092.14 | H5: ='BRP277 150 S3'!I58 -> #N/A | I5: =H5-G5 -> #N/A | J5: =I5/G5 -> #N/A
B6: 4 | C6: 919615893874 | D6: BRP277 LED195 CW M2 SLR PSU SPD S3 | E6: 30302122 | F6: BRP277 S3 5.7K 150W SPD | G6: 2151 | H6: ='BRP277 150 SPD S3'!I59 -> #N/A | I6: =H6-G6 -> #N/A | J6: =I6/G6 -> #N/A
B7: 5 | C7: 919615893875 | D7: BRP267 LED180 CW M2 SLR PSU ELP S2 | E7: NA | F7: NA | G7: 2007.05 | H7: =H3 -> 2284.1867 | I7: =H7-G7 -> 277.13668 | J7: =I7/G7 -> 0.1380816 | L7: 2151
B8: 6 | C8: 919615893876 | D8: BRP267 LED180 CW M2 SLR PSU SPD ELP S2 | E8: NA | F8: NA | G8: 2066.17 | H8: =H4 -> #N/A | I8: =H8-G8 -> #N/A | J8: =I8/G8 -> #N/A

Sheet L2
C2: 20405419 | D2: LBRD PH R1 STL 150W 36L 5.7K-6A
B3: Type | C3: No. | D3: Description | E3: Quantity | F3: UoM Name | G3: Unit Price | H3: Total
B4: Item | C4: 10106144 | D4: LED-BRG-5050-6W-5700K-1A-70-B4-BO/BP-T&R(06A) | E4: 36 | F4: NOS | G4: 7.6 | H4: =G4*E4 -> 273.6
B5: Item | C5: 10403005 | D5: NC-SOLDER-PASTE-LEAD-FREE-PF-609-P-20-38-T3 | E5: 0.001 | F5: KGS | G5: 7500 | H5: =G5*E5 -> 7.5
B6: Item | C6: 10301003 | D6: 2-PIN-POKE-IN-SMD-CONNECTOR | E6: 1 | F6: NOS | G6: 3.15 | H6: =G6*E6 -> 3.15
B7: Item | C7: 10101598 | D7: MPCB-JI-SL-5050-18S2P-36L-120.2x110.2MM-R1 | E7: 1 | F7: NOS | G7: 68.78 | H7: =G7*E7 -> 68.78 | J7: =120.2*110.2/100 -> 132.4604 | K7: =J7*0.5 -> 66.2302
B8: Total | H8: =SUM(H4:H7) -> 353.03
C10: Assembly Cost
C11: SMD | D11: 2 SOLDER PADS | E11: =E4 -> 36 | F11: 0.11 | G11: =E11*F11 -> 3.96
C12: Testing | E12: 1 | F12: 1 | G12: =E12*F12 -> 1
C13: Total Value Addition | G13: =SUM(G11:G12) -> 4.96
C14: BOM cost | G14: =H8 -> 353.03
C15: Total | G15: =SUM(G13:G14) -> 357.99
C17: 20405423 | D17: LBRD PH R1 STL 150W 36L 5.7K-6C
B18: Type | C18: No. | D18: Description | E18: Quantity | F18: UoM Name | G18: Unit Price | H18: Total
B19: Item | C19: 10106302 | D19: LED-BRG-5050-6W-5700K-750mA-70-160-5.8-6.2-5-T&R(06C) | E19: 36 | F19: NOS | G19: 10.5 | H19: =G19*E19 -> 378
B20: Item | C20: 10403005 | D20: NC-SOLDER-PASTE-LEAD-FREE-PF-609-P-20-38-T3 | E20: 0.001 | F20: KGS | G20: 7500 | H20: =G20*E20 -> 7.5
B21: Item | C21: 10301003 | D21: 2-PIN-POKE-IN-SMD-CONNECTOR | E21: 1 | F21: NOS | G21: 3.15 | H21: =G21*E21 -> 3.15
B22: Item | C22: 10101598 | D22: MPCB-JI-SL-5050-18S2P-36L-120.2x110.2MM-R1 | E22: 1 | F22: NOS | G22: 68.78 | H22: =G22*E22 -> 68.78
B23: Total | H23: =SUM(H19:H22) -> 457.43
C25: Assembly Cost
C26: SMD | D26: 2 SOLDER PADS | E26: =E19 -> 36 | F26: 0.11 | G26: =E26*F26 -> 3.96
C27: Testing | E27: 1 | F27: 1 | G27: =E27*F27 -> 1
C28: Total Value Addition | G28: =SUM(G26:G27) -> 4.96
C29: BOM cost | G29: =H23 -> 457.43
C30: Total | G30: =SUM(G28:G29) -> 462.39

Sheet Driver
B2: 20603182 | C2: MI-DRVR-R1-STL-108V_625mA-75W-MT7939C2 (FOR 150W ST-5050)
B3: No. | C3: Description | D3: Quantity | E3: UoM Name | F3: Unit Price | G3: Position | H3: TOTAL
B4: 20503187 | C4: AI-DRVR-R1-STL-108V_625mA-75W-MT7939C2 (FOR 150W ST-5050) | D4: 1 | E4: NOS | F4: 0 | H4: =F4*D4 -> 0
B5: 20202157 | C5: ECL R1 STL DRVR BOX COVER PLATE 80W-120W-GI BLK | D5: 1 | E5: NOS | F5: 6 | H5: =F5*D5 -> 6
B6: 20202156 | C6: ECL R1 STL DRVR BOX 80W-120W BLK | D6: 1 | E6: NOS | F6: 13.5 | H6: =F6*D6 -> 13.5
B7: 10403275 | C7: IPA | D7: 0.0015 | E7: LTR | F7: 340 | H7: =F7*D7 -> 0.51
B8: 10403153 | C8: CONFORMAL-COATING | D8: 0.5 | E8: ML | F8: 0.72 | H8: =F8*D8 -> 0.36
B9: 10403093 | C9: ENCAPSULANT-SILICON-MAXTOR-TC-MT2803/04-B | D9: 0.05 | E9: KGS | F9: 176 | H9: =F9*D9 -> 8.8
B10: 10403092 | C10: ENCAPSULANT-SILICON-MAXTOR-TC-MT2803/04-A | D10: 0.05 | E10: KGS | F10: 176 | H10: =F10*D10 -> 8.8
B11: 10403049 | C11: SOLDER-BAR-ROHS-SCNG/SNG | D11: 0.001 | E11: KGS | F11: 6202 | H11: =F11*D11 -> 6.202
B12: 10403018 | C12: STICKER-PAPER-12X18 INCH | D12: 0.04 | E12: NOS | F12: 13 | H12: =F12*D12 -> 0.52
B13: 10403012 | C13: NO CLEAN FLUX 2CARBOUY JF-927 PAI | D13: 0.001 | E13: LTR | F13: 355 | H13: =F13*D13 -> 0.355
B14: 10403009 | C14: SOLDER-WIRE-99.3/0.7-0.9mm-ROHs | D14: 0.0002 | E14: KGS | F14: 6359 | H14: =F14*D14 -> 1.2718
B15: 10307150 | C15: JI-HSNK-FOR-MOSFET-35.5X27.5X3MM | D15: 1 | E15: NOS | F15: 7.56 | H15: =F15*D15 -> 7.56
... B23: 10302001 | C23: SS-PAN-COMB-SCREW-M3x6 | D23: 1 | E23: NOS | F23: 0.25 | H23: =F23*D23 -> 0.25
B24: 10301622 | C24: WIRE-PVC-FR-1Cx0.75SQMM-RED-1100V | D24: 0.15 | E24: MTR | F24: 9.15 | G24: + | H24: =F24*D24 -> 1.3725
B25: 10301621 | C25: WIRE-PVC-FR-1Cx0.75SQMM-GREY-1100V | D25: 0.15 | E25: MTR | F25: 8.54 | G25: L | H25: =F25*D25 -> 1.281
B26: 10301620 | C26: WIRE-PVC-FR-1Cx0.75SQMM-BLK-1100V | D26: 0.15 | E26: MTR | F26: 8.54 | G26: - | H26: =F26*D26 -> 1.281
B27: 10301273 | C27: WIRE-PVC-FR-1Cx0.75SQMM-BLUE-1100V | D27: 0.15 | E27: MTR | F27: 9.15 | G27: N | H27: =F27*D27 -> 1.3725
B28: 10301165 | C28: WIRE-PVC-EARTHING-0.75SQ.MM-YL/GRN-WITH-LUG-150MM | D28: 1 | E28: NOS | F28: 2.92 | H28: =F28*D28 -> 2.92
B29: 10301135 | C29: WIRE-TEFLON-7X31-SWG-WHT-50mm | D29: 1 | E29: NOS | F29: 0.54 | G29: AA' | H29: =F29*D29 -> 0.54
B30: 10301105 | C30: WIRE-PVC-EARTHING-0.75SQ.MM-YL/GRN-WITH-LUG-100MM | D30: 1 | E30: NOS | F30: 2.35 | G30: E | H30: =F30*D30 -> 2.35
B31: 10207110 | C31: TRX-PQ2625-VT(6+6)-0.330mH-5%-Tray | D31: 1 | E31: NOS | F31: 38.65 | G31: TRX1 | H31: =F31*D31 -> 38.65
B32: 10207018 | C32: IND-RAD-12x15(P7.5)-2mH-10%-Tray-105902 (2040018) | D32: 1 | E32: NOS | F32: 10.8 | G32: LF1 | H32: =F32*D32 -> 10.8
B33: 10206071 | C33: FUSE-SCH-STD-BOX-SLOW BLOW-10A-250VAC-5MM-T&R | D33: 1 | E33: NOS | F33: 2.3 | G33: F1 | H33: =F33*D33 -> 2.3
B34: 10206060 | C34: MOV-14D-275V-STD-P7.5mm-TVR14D431KSY-Bulk | D34: 1 | E34: NOS | F34: 4 | G34: VR4 | H34: =F34*D34 -> 4
B35: 10206016 | C35: MOV-14D-395V-P10mm-TVR TVR14621KSUD2Y -Bulk | D35: 1 | E35: NOS | F35: 3.75 | G35: VR3 | H35: =F35*D35 -> 3.75
B36: 10206002 | C36: MOV-10D-320V-STD-P7.5mm-TVR10511KSY-Bulk | D36: 2 | E36: NOS | F36: 2.15 | G36: VR1,VR2 | H36: =F36*D36 -> 4.3
B37: 10204059 | C37: FET-N-CH-TO220F-10A-800V-WL10N80M3-TUBE-CYG | D37: 1 | E37: NOS | F37: 23.7 | G37: Q1 | H37: =F37*D37 -> 23.7
B38: 10204050 | C38: BR-GP-KBP-3A-1000V-KBP310G-Tube-JF | D38: 1 | E38: NOS | F38: 4 | G38: BR | H38: =F38*D38 -> 4
B39: 10203122 | C39: ECAP-220UF-160V-16x26MM-10K HRS-105C-20%-BERYL | D39: 1 | E39: NOS | F39: 15.75 | G39: C5 | H39: =F39*D39 -> 15.75
B40: 10203117 | C40: CAP-AISHI-RJ SERISE-10000HRS-5x11-22uF-50V/63V-20%-Bulk | D40: 1 | E40: NOS | F40: 0.81 | G40: C3 | H40: =F40*D40 -> 0.81
... B45: 10202014 | C45: JUMPER-COPPER-WIRE-DIA-0.6mm-60MM-T&R | D45: 1 | E45: NOS | F45: 0.09 | G45: LF1 | H45: =F45*D45 -> 0.09
H46: =SUM(H4:H45) -> 185.0758
B48: 20503187 | C48: AI-DRVR-R1-STL-108V_625mA-75W-MT7939C2 (FOR 150W ST-5050) | D48: 1
B49: No. | C49: Description | D49: Quantity | E49: UoM Name | F49: Unit Price | G49: Position | H49: TOTAL
B50: 10403216 | C50: SMT-RED GLUE-PAI-999 | D50: 0.001 | E50: GMS | F50: 8.5 | H50: =F50*D50 -> 0.0085
B51: 10206061 | C51: SIDACTOR-JP15SB | D51: 1 | E51: NOS | F51: 3.2 | G51: SD1 | H51: =F51*D51 -> 3.2
B52: 10201176 | C52: DRVR-PCB-JI-ST-MX60-80W-R2 | D52: 1 | E52: NOS | F52: 9.5 | H52: =F52*D52 -> 9.5
B53: 10105024 | C53: IC-MT7939-MAXICI-SOIC8-C2 | D53: 1 | E53: NOS | F53: 6.25 | G53: U1 | H53: =F53*D53 -> 6.25
...

Sheet SPD
B2: 20602342 | C2: MI-SPD-R1-10KV-HS
B3: No. | C3: Description | D3: Quantity | E3: UoM Name | F3: Position | G3: Unit Price | H3: Total
B4: 10201205 | C4: DRVR-PCB-JI-SPD-R1-10KV | D4: 1 | E4: NOS | G4: 3.25 | H4: =D4*G4 -> 3.25
B5: 10206076 | C5: MOV-20D-275V-P10mm-TVR20431KSU22Y-Bulk | D5: 1 | E5: NOS | F5: MOV1 | G5: 8.5 | H5: =D5*G5 -> 8.5
B6: 10206028 | C6: GDT-8D-800V-GD82R800-Bulk | D6: 1 | E6: NOS | F6: GDT1 | G6: 11.75 | H6: =D6*G6 -> 11.75
B7: 10301240 | C7: HEAT-SHRINK-SLEEVE-BLK-Ø30 | D7: 0.075 | E7: MTR | G7: 46 | H7: =D7*G7 -> 3.45
B8: 10303766 | C8: POLY-PAPER-10KV-UNV-SPD(57X37X0.18MM) | D8: 1 | E8: NOS | G8: 0.3 | H8: =D8*G8 -> 0.3
B9: 10206070 | C9: GDT-6D-600V-GD52R600-Bulk | D9: 1 | E9: NOS | F9: GDT2 | G9: 10.5 | H9: =D9*G9 -> 10.5
B10: 10206077 | C10: FUSE-STD-AXIAL-GLASS(3.6X10)-SLOW BLOW-15A-250VAC-**-T&R | D10: 1 | E10: NOS | F10: FUSE | G10: 5.8 | H10: =D10*G10 -> 5.8
B11: 10403049 | C11: SOLDER-BAR-ROHS-SCNG/SNG | D11: 0.0015 | E11: KGS | G11: 6202 | H11: =D11*G11 -> 9.303
B12: 10403009 | C12: SOLDER-WIRE-99.3/0.7-0.9mm-ROHs | D12: 1e-05 | E12: KGS | G12: 6359 | H12: =D12*G12 -> 0.06359
B13: 10306419 | C13: NON TEARABLE STICKER 15X23MM | D13: 1 | E13: NOS | G13: 0.15 | H13: =D13*G13 -> 0.15
B14: 10403012 | C14: NO CLEAN FLUX 2CARBOUY JF-927 PAI | D14: 0.0015 | E14: LTR | G14: 355 | H14: =D14*G14 -> 0.5325
B15: 10403153 | C15: CONFORMAL-COATING | D15: 0.4 | E15: ML | G15: 0.72 | H15: =D15*G15 -> 0.288
B16: 10403018 | C16: STICKER-PAPER-12"X18" | D16: 0.02 | E16: NOS | G16: 13 | H16: =D16*G16 -> 0.26
B17: 10403275 | C17: IPA | D17: 0.0015 | E17: LTR | G17: 340 | H17: =D17*G17 -> 0.51
B18: 10301622 | C18: WIRE-PVC-FR-1Cx0.75SQMM-RED-1100V | D18: 0.115 | E18: MTR | G18: 8.54 | H18: =D18*G18 -> 0.9821
B19: 10301272 | C19: WIRE-PVC-FR-1Cx0.75SQMM-BROWN-1100V | D19: 0.23 | E19: MTR | G19: 8.54 | H19: =D19*G19 -> 1.9642
H20: =SUM(H4:H19) -> 57.60339
G21: AI | H21: 0
G22: MI | H22: =H20 -> 57.60339
G23: Total | H23: =SUM(H21:H22) -> 57.60339
G24: Assembly (15%) | H24: =H23*15% -> 8.6405085
G25: Grand total | H25: =SUM(H23:H24) -> 66.243898

Sheet CASTING
D3: Particulars | E3: ADC12 | F3: MELTING LOSS | G3: Driling charges /hole | H3: Taping charges /hole | I3: Powder coating
D4: Rate | E4: 360 | F4: 0.06 | G4: 0.35 | H4: 0.35 | I4: 0.11
B7: Sr No | C7: 12NC/Ji Code | D7: Description | E7: PDC COST BREAKUP | L7: Machining Cost Breakup | Q7: Powder coating | S7: Total
E8: Weight(kg) | F8: Melting Loss(kg) | G8: Chargeble Weight (kg) | H8: Cost of bare housing / nos | I8: shot charges/nos | J8: Fetling & Grinding/ Nos | K8: Pdc cost/ piece | L8: Number of Drill hole | M8: Number of Tap | N8: Driling cost | O8: Taping cost | P8: Total Maching Cost / Piece | Q8: Sq Inch | R8: cost
B9: 1 | D9: CS-45W HOUSING | E9: 1.41 | F9: =E9*F$4 -> 0.0846 | G9: =F9+E9 -> 1.4946 | H9: =G9*E$4 -> 538.056 | I9: 65 | J9: 3 | K9: =SUM(I9,H9,J9) -> 606.056 | L9: 37 | M9: 37 | N9: =L9*G4 -> 12.95 | O9: =M9*H4 -> 12.95 | P9: =SUM(O9,N9) -> 25.9 | Q9: 540.5 | R9: =Q9*I$4 -> 59.455 | S9: =R9+P9+K9 -> 691.411
B10: 2 | D10: CS -45W LENS PLATE | E10: 0.26 | F10: =E10*F$4 -> 0.0156 | G10: =F10+E10 -> 0.2756 | H10: =G10*E$4 -> 99.216 | I10: 22 | J10: 2 | K10: =SUM(I10,H10,J10) -> 123.216 | L10: 12 | M10: 12 | N10: =L10*G4 -> 4.2 | O10: =M10*H4 -> 4.2 | P10: =SUM(O10,N10) -> 8.4 | Q10: 151 | R10: =Q10*I$4 -> 16.61 | S10: =R10+P10+K10 -> 148.226

Sheet BRP277 150 S2
C2: 919615893871 | E2: BRP277 LED180 CW M2 SLR PSU S2
C3: 30302118 | E3: BRP277 S2 5.7K 150W
A4: Item Sub Sub Group | B4: ItemSubgroup | C4: Category | D4: No. | E4: Description | F4: Quantity | G4: UoM Name | H4: Unit Price | I4: Position | J4: Total
A5: =VLOOKUP(D4:D50,[1]Sheet1!$A:$K,11,0) -> GREY | B5: =VLOOKUP(D4:D50,[1]Sheet1!$A:$L,12,0) -> PCT | C5: HOUSING | D5: 20203439 | E5: PH-R1-STL-JA-BACK-COVER-PDC-150W-GRY-RAL-7011 | F5: 1 | G5: NOS | H5: =CASTING!S10 -> 148.226 | I5: BACK COVER | J5: =H5*F5 -> 148.226
A6: =VLOOKUP(D5:D51,[1]Sheet1!$A:$K,11,0) -> GREY | B6: =VLOOKUP(D5:D51,[1]Sheet1!$A:$L,12,0) -> PCT | C6: HOUSING | D6: 20203438 | E6: PH-R1-STL-JA-HSG-PDC-150W-GRY-RAL-7011 | F6: 1 | G6: NOS | H6: =CASTING!S9 -> 691.411 | I6: HOUSING | J6: =H6*F6 -> 691.411
A7: =VLOOKUP(D6:D52,[1]Sheet1!$A:$K,11,0) -> SILICON | B7: =VLOOKUP(D6:D52,[1]Sheet1!$A:$L,12,0) -> Hardware | C7: HOUSING | D7: 10304138 | E7: PH-R1-STL-JA-BACK COVER-PDC-150W-MOULDED-SILICON GASKET | F7: 1 | G7: NOS | H7: 23 | I7: BACK COVER GASKET | J7: =H7*F7 -> 23
A8: =VLOOKUP(D7:D53,[1]Sheet1!$A:$K,11,0) -> SILICON | B8: =VLOOKUP(D7:D53,[1]Sheet1!$A:$L,12,0) -> Hardware | C8: HOUSING | D8: 10304117 | E8: SILICON GASKET-LENS-R1-STL-BO-241-242 | F8: 1 | G8: NOS | H8: 8.5 | I8: LENS GASKET | J8: =H8*F8 -> 8.5
A9: =VLOOKUP(D8:D54,[1]Sheet1!$A:$K,11,0) -> PLASTIC PMMA | B9: =VLOOKUP(D8:D54,[1]Sheet1!$A:$L,12,0) -> Hardware | C9: HOUSING | D9: 10303986 | E9: LENS-R1-STL-BO241-5050-36X1-120W(5302) | F9: 1 | G9: NOS | H9: 92 | I9: LENS | J9: =H9*F9 -> 92
A10: =VLOOKUP(D9:D55,[1]Sheet1!$A:$K,11,0) -> #N/A | B10: =VLOOKUP(D9:D55,[1]Sheet1!$A:$L,12,0) -> #N/A | J10: =SUM(J5:J9) -> 963.137
A11: =VLOOKUP(D10:D56,[1]Sheet1!$A:$K,11,0) -> BOXED | B11: =VLOOKUP(D10:D56,[1]Sheet1!$A:$L,12,0) -> DRV | C11: ELEC. | D11: 20603182 | E11: MI-DRVR-R1-STL-108V_625mA-75W-MT7939C2 (FOR 150W ST-5050) | F11: 2 | G11: NOS | H11: =Driver!H79 -> 252.39544 | I11: DRIVER | J11: =H11*F11 -> 504.79089
A12: =VLOOKUP(D11:D57,[1]Sheet1!$A:$K,11,0) -> 5700 CCT | B12: =VLOOKUP(D11:D57,[1]Sheet1!$A:$L,12,0) -> LED SMT | C12: ELEC. | D12: 20405419 | E12: LBRD PH R1 STL 150W 36L 5.7K-6A | F12: 1 | G12: NOS | H12: ='L2'!G15 -> 357.99 | I12: LED ENGINE | J12: =H12*F12 -> 357.99
A13: =VLOOKUP(D12:D58,[1]Sheet1!$A:$K,11,0) -> #N/A | B13: =VLOOKUP(D12:D58,[1]Sheet1!$A:$L,12,0) -> #N/A | J13: =SUM(J11:J12) -> 862.78089
A14: =VLOOKUP(D13:D59,[1]Sheet1!$A:$K,11,0) -> CONSUMABLE | B14: =VLOOKUP(D13:D59,[1]Sheet1!$A:$L,12,0) -> Others | C14: HARDWARE | D14: 10403049 | E14: SOLDER-BAR-ROHS-SCNG/SNG | F14: 0.0006 | G14: KGS | H14: 6202 | I14: WIRE DIPING | J14: =H14*F14 -> 3.7212
A15: =VLOOKUP(D14:D60,[1]Sheet1!$A:$K,11,0) -> CONSUMABLE | B15: =VLOOKUP(D14:D60,[1]Sheet1!$A:$L,12,0) -> Others | C15: HARDWARE | D15: 10403047 | E15: FIBRE-GLASS-SLEEVE-H-CLASS-6MM | F15: 0.2 | G15: MTR | H15: 6.75 | I15: AC DRIVER WIRE | J15: =H15*F15 -> 1.35
A16: =VLOOKUP(D15:D61,[1]Sheet1!$A:$K,11,0) -> METAL | B16: =VLOOKUP(D15:D61,[1]Sheet1!$A:$L,12,0) -> Hardware | C16: HARDWARE | D16: 10307261 | E16: SS-PAN-COMB-WITH-WASHER-SCREW-M3X8(304) | F16: 5 | G16: NOS | H16: 0.35 | I16: DRIVER FIXING + EARTHING | J16: =H16*F16 -> 1.75
A17: =VLOOKUP(D16:D62,[1]Sheet1!$A:$K,11,0) -> METAL | B17: =VLOOKUP(D16:D62,[1]Sheet1!$A:$L,12,0) -> Hardware | C17: HARDWARE | D17: 10307175 | E17: SS-PAN-COMB-SCREW-M4X25(304) | F17: 8 | G17: NOS | H17: 0.9 | I17: FOR BACK COVER FIXING | J17: =H17*F17 -> 7.2
A18: =VLOOKUP(D17:D63,[1]Sheet1!$A:$K,11,0) -> METAL | B18: =VLOOKUP(D17:D63,[1]Sheet1!$A:$L,12,0) -> Hardware | C18: HARDWARE | D18: 10307174 | E18: SS-PAN-COMB-SCREW-M4x20(304) | F18: 2 | G18: NOS | H18: 0.68 | I18: FOR BACK COVER FIXING | J18: =H18*F18 -> 1.36
A19: =VLOOKUP(D18:D64,[1]Sheet1!$A:$K,11,0) -> METAL | B19: =VLOOKUP(D18:D64,[1]Sheet1!$A:$L,12,0) -> Hardware | C19: HARDWARE | D19: 10307173 | E19: SS-HEX-HEX.BOLT-M8X35(304) | F19: 2 | G19: NOS | H19: 4.1 | I19: POLE MOUNTING | J19: =H19*F19 -> 8.2
A20: =VLOOKUP(D19:D65,[1]Sheet1!$A:$K,11,0) -> CONSUMABLE | B20: =VLOOKUP(D19:D65,[1]Sheet1!$A:$L,12,0) -> Others | C20: HARDWARE | D20: 10403294 | E20: THERMAL PASTE-WACKER-5TC-3073 | F20: 0.0024 | G20: KGS | H20: 2700 | I20: ON PCB | J20: =H20*F20 -> 6.48
A21: =VLOOKUP(D20:D66,[1]Sheet1!$A:$K,11,0) -> CONSUMABLE | B21: =VLOOKUP(D20:D66,[1]Sheet1!$A:$L,12,0) -> Others | C21: HARDWARE | D21: 10403225 | E21: SILICON SEALANT FEVI SEAL NEUTRAL PRO | F21: 0.00065 | G21: ML | H21: 0.5 | I21: DC WIRE OUTPUT | J21: =H21*F21 -> 0.000325
A22: =VLOOKUP(D21:D67,[1]Sheet1!$A:$K,11,0) -> PLASTIC PMMA | B22: =VLOOKUP(D21:D67,[1]Sheet1!$A:$L,12,0) -> Hardware | C22: HARDWARE | D22: 10303301 | E22: NYLON-CABLE-GLAND-PG9-12MM-WITH-WASHER-POWER CONNECT-BLK | F22: 1 | G22: NOS | H22: 4.75 | I22: CABLE ENTRY GLAND | J22: =H22*F22 -> 4.75
A23: =VLOOKUP(D22:D68,[1]Sheet1!$A:$K,11,0) -> PLASTIC PMMA | B23: =VLOOKUP(D22:D68,[1]Sheet1!$A:$L,12,0) -> Hardware | C23: HARDWARE | D23: 10303182 | E23: HEAT-SHRINK-SLEEVE-WHT-Ø4 | F23: 0.1 | G23: MTR | H23: 4.2 | I23: ON DC WIRES | J23: =H23*F23 -> 0.42
A24: =VLOOKUP(D23:D69,[1]Sheet1!$A:$K,11,0) -> PLASTIC PMMA | B24: =VLOOKUP(D23:D69,[1]Sheet1!$A:$L,12,0) -> Hardware | C24: HARDWARE | D24: 10303122 | E24: FIBRE-WASHER-M3 | F24: 10 | G24: NOS | H24: 0.11 | I24: PCB FIXING | J24: =H24*F24 -> 1.1
A25: =VLOOKUP(D24:D70,[1]Sheet1!$A:$K,11,0) -> METAL | B25: =VLOOKUP(D24:D70,[1]Sheet1!$A:$L,12,0) -> Hardware | C25: HARDWARE | D25: 10302740 | E25: SS-PAN-PH-SCREW-M3x8(304) | F25: 14 | G25: NOS | H25: 0.31 | I25: LENS FIXING | J25: =H25*F25 -> 4.34
... A34: =VLOOKUP(D33:D79,[1]Sheet1!$A:$K,11,0) -> CONNECTOR & HARNESS | B34: =VLOOKUP(D33:D79,[1]Sheet1!$A:$L,12,0) -> Hardware | C34: HARDWARE | D34: 10301024 | E34: WIRE-PVC-SINGLE-CORE-0.5SQ.MM-YL/GRN-WITH-EARTHING-LUG-150MM | F34: 1 | G34: NOS | H34: 2.33 | I34: FOR EARTHING | J34: =H34*F34 -> 2.33
A35: =VLOOKUP(D34:D80,[1]Sheet1!$A:$K,11,0) -> #N/A | B35: =VLOOKUP(D34:D80,[1]Sheet1!$A:$L,12,0) -> #N/A | J35: =SUM(J14:J34) -> 78.521525
A36: =VLOOKUP(D35:D81,[1]Sheet1!$A:$K,11,0) -> CONSUMABLE | B36: =VLOOKUP(D35:D81,[1]Sheet1!$A:$L,12,0) -> Others | C36: PACKING | D36: 10403110 | E36: TESTED-OK-STKR | F36: 1 | G36: NOS | H36: 0.23 | I36: PACKING | J36: =H36*F36 -> 0.23
A37: =VLOOKUP(D36:D82,[1]Sheet1!$A:$K,11,0) -> CONSUMABLE | B37: =VLOOKUP(D36:D82,[1]Sheet1!$A:$L,12,0) -> Others | C37: PACKING | D37: 10403086 | E37: SILVER-STICKER-PAPER-NON-TEARABLE-12"X18" | F37: 0.0041 | G37: NOS | H37: 17 | I37: PACKING | J37: =H37*F37 -> 0.0697
A38: =VLOOKUP(D37:D83,[1]Sheet1!$A:$K,11,0) -> CONSUMABLE | B38: =VLOOKUP(D37:D83,[1]Sheet1!$A:$L,12,0) -> Others | C38: PACKING | D38: 10403075 | E38: PLAIN-PAPER-A4-SIZE | F38: 1 | G38: NOS | H38: 0.52 | I38: IM SHEET | J38: =H38*F38 -> 0.52
A39: =VLOOKUP(D38:D84,[1]Sheet1!$A:$K,11,0) -> CONSUMABLE | B39: =VLOOKUP(D38:D84,[1]Sheet1!$A:$L,12,0) -> Others | C39: PACKING | D39: 10403018 | E39: STICKER-PAPER-12X18 INCH | F39: 0.25 | G39: NOS | H39: 9 | I39: PACKING | J39: =H39*F39 -> 2.25
A40: =VLOOKUP(D39:D85,[1]Sheet1!$A:$K,11,0) -> PACKAGING | B40: =VLOOKUP(D39:D85,[1]Sheet1!$A:$L,12,0) -> Hardware | C40: PACKING | D40: 10308672 | E40: POLYBAG-10"X22"-65µ | F40: 1 | G40: NOS | H40: 3 | I40: PACKING | J40: =H40*F40 -> 3
A41: =VLOOKUP(D40:D86,[1]Sheet1!$A:$K,11,0) -> PACKAGING | B41: =VLOOKUP(D40:D86,[1]Sheet1!$A:$L,12,0) -> Hardware | C41: PACKING | D41: 10308671 | E41: MASTER CARTON PH R1 STL 150W | F41: 1 | G41: NOS | H41: 38.02 | I41: PACKING | J41: =H41*F41 -> 38.02
A42: =VLOOKUP(D41:D87,[1]Sheet1!$A:$K,11,0) -> PACKAGING | B42: =VLOOKUP(D41:D87,[1]Sheet1!$A:$L,12,0) -> Hardware | C42: PACKING | D42: 10308670 | E42: PADDING-PART2-L208 X W100-PH R1 STL 150W | F42: 2 | G42: NOS | H42: 1.73 | I42: PACKING | J42: =H42*F42 -> 3.46
A43: =VLOOKUP(D42:D88,[1]Sheet1!$A:$K,11,0) -> PACKAGING | B43: =VLOOKUP(D42:D88,[1]Sheet1!$A:$L,12,0) -> Hardware | C43: PACKING | D43: 10308669 | E43: PADDING-PART1-L475 X W100-PH R1 STL 150W | F43: 2 | G43: NOS | H43: 3.35 | I43: PACKING | J43: =H43*F43 -> 6.7
A44: =VLOOKUP(D43:D89,[1]Sheet1!$A:$K,11,0) -> PACKAGING | B44: =VLOOKUP(D43:D89,[1]Sheet1!$A:$L,12,0) -> Hardware | C44: PACKING | D44: 10306734 | E44: SILVER STICKER 80X30MM | F44: 1.5 | G44: NOS | H44: 1.75 | I44: PACKING | J44: =H44*F44 -> 2.625
A45: =VLOOKUP(D44:D90,[1]Sheet1!$A:$K,11,0) -> PACKAGING | B45: =VLOOKUP(D44:D90,[1]Sheet1!$A:$L,12,0) -> Hardware | C45: PACKING | D45: 10306703 | E45: PHILIPS PACKING TAPE 2" | F45: 0.375 | G45: MTR | H45: 0.5384 | I45: PACKING | J45: =H45*F45 -> 0.2019
A46: =VLOOKUP(D45:D91,[1]Sheet1!$A:$K,11,0) -> PACKAGING | B46: =VLOOKUP(D45:D91,[1]Sheet1!$A:$L,12,0) -> Hardware | C46: PACKING | D46: 10306683 | E46: HEAT-SEAL-PACKING-STRAP | F46: 0.7 | G46: MTR | H46: 0.5425 | I46: PACKING | J46: =H46*F46 -> 0.37975
A47: =VLOOKUP(D46:D92,[1]Sheet1!$A:$K,11,0) -> PACKAGING | B47: =VLOOKUP(D46:D92,[1]Sheet1!$A:$L,12,0) -> Hardware | C47: PACKING | D47: 10306626 | E47: PLAIN STICKER 40X15MM | F47: 1 | G47: NOS | H47: 0.15 | I47: PACKING | J47: =H47*F47 -> 0.15
... A50: =VLOOKUP(D49:D95,[1]Sheet1!$A:$K,11,0) -> PACKAGING | B50: =VLOOKUP(D49:D95,[1]Sheet1!$A:$L,12,0) -> Hardware | C50: PACKING | D50: 10306207 | E50: TRANSPARENT-TAPE | F50: 0.00643 | G50: NOS | H50: 32 | I50: PACKING | J50: =H50*F50 -> 0.20576
A51: =VLOOKUP(D50:D96,[1]Sheet1!$A:$K,11,0) -> #N/A | B51: =VLOOKUP(D50:D96,[1]Sheet1!$A:$L,12,0) -> #N/A | J51: =SUM(J36:J50) -> 58.91211
...

Sheet BRP277 150 SPD S2
B2: 919615893872 | D2: BRP277 LED180 CW M2 SLR PSU SPD S2
B3: 30302117 | D3: BRP277 S2 5.7K 150W SPD
B4: Category | C4: No. | D4: Description | E4: Quantity | F4: UoM Name | G4: Unit Price | H4: Position | I4: Total
B5: HOUSING | C5: 20203439 | D5: PH-R1-STL-JA-BACK-COVER-PDC-150W-GRY-RAL-7011 | E5: 1 | F5: NOS | G5: =VLOOKUP(C5,'BRP277 150 S2'!D4:J51,5,0) -> 148.226 | H5: BACK COVER | I5: =G5*E5 -> 148.226
B6: HOUSING | C6: 20203438 | D6: PH-R1-STL-JA-HSG-PDC-150W-GRY-RAL-7011 | E6: 1 | F6: NOS | G6: =VLOOKUP(C6,'BRP277 150 S2'!D5:J52,5,0) -> 691.411 | H6: HOUSING | I6: =G6*E6 -> 691.411
B7: HOUSING | C7: 10304138 | D7: PH-R1-STL-JA-BACK COVER-PDC-150W-MOULDED-SILICON GASKET | E7: 1 | F7: NOS | G7: =VLOOKUP(C7,'BRP277 150 S2'!D6:J53,5,0) -> 23 | H7: BACK COVER GASKET | I7: =G7*E7 -> 23
B8: HOUSING | C8: 10304117 | D8: SILICON GASKET-LENS-R1-STL-BO-241-242 | E8: 1 | F8: NOS | G8: =VLOOKUP(C8,'BRP277 150 S2'!D7:J54,5,0) -> 8.5 | H8: LENS GASKET | I8: =G8*E8 -> 8.5
B9: HOUSING | C9: 10303986 | D9: LENS-R1-STL-BO241-5050-36X1-120W(5302) | E9: 1 | F9: NOS | G9: =VLOOKUP(C9,'BRP277 150 S2'!D8:J55,5,0) -> 92 | H9: LENS | I9: =G9*E9 -> 92
I10: =SUM(I5:I9) -> 963.137
B11: ELEC. | C11: 20603182 | D11: MI-DRVR-R1-STL-108V_625mA-75W-MT7939C2 (FOR 150W ST-5050) | E11: 2 | F11: NOS | G11: =VLOOKUP(C11,'BRP277 150 S2'!D10:J57,5,0) -> 252.39544 | H11: DRIVER | I11: =G11*E11 -> 504.79089
B12: ELEC. | C12: 20602342 | D12: MI-SPD-R1-10KV-HS | E12: 1 | F12: NOS | G12: =SPD!H25 -> 66.243898 | H12: SPD | I12: =G12*E12 -> 66.243898
B13: ELEC. | C13: 20405419 | D13: LBRD PH R1 STL 150W 36L 5.7K-6A | E13: 1 | F13: NOS | G13: =VLOOKUP(C13,'BRP277 150 S2'!C59:I59,5,0) -> #N/A | I13: =G13*E13 -> #N/A
I14: =SUM(I11:I13) -> #N/A
B15: HARDWARE | C15: 10403294 | D15: THERMAL PASTE-WACKER-5TC-3073 | E15: 0.0024 | F15: KGS | G15: =VLOOKUP(C15,'BRP277 150 S2'!D14:H51,5,0) -> 2700 | H15: ON PCB | I15: =G15*E15 -> 6.48
B16: HARDWARE | C16: 10403225 | D16: SILICON SEALANT FEVI SEAL NEUTRAL PRO | E16: 0.00065 | F16: ML | G16: =VLOOKUP(C16,'BRP277 150 S2'!D15:H52,5,0) -> 0.5 | H16: DC WIRE OUTPUT | I16: =G16*E16 -> 0.000325
B17: HARDWARE | C17: 10403049 | D17: SOLDER-BAR-ROHS-SCNG/SNG | E17: 0.0006 | F17: KGS | G17: 5315 | H17: WIRE DIPING | I17: =G17*E17 -> 3.189
B18: HARDWARE | C18: 10403047 | D18: FIBRE-GLASS-SLEEVE-H-CLASS-6MM | E18: 0.2 | F18: MTR | G18: 6.75 | H18: AC DRIVER WIRE | I18: =G18*E18 -> 1.35
B19: HARDWARE | C19: 10307261 | D19: SS-PAN-COMB-WITH-WASHER-SCREW-M3X8(304) | E19: 5 | F19: NOS | G19: 0.35 | H19: DRIVER FIXING + EARTHING | I19: =G19*E19 -> 1.75
B20: HARDWARE | C20: 10307175 | D20: SS-PAN-COMB-SCREW-M4X25(304) | E20: 8 | F20: NOS | G20: 0.9 | H20: FOR BACK COVER FIXING | I20: =G20*E20 -> 7.2
B21: HARDWARE | C21: 10307174 | D21: SS-PAN-COMB-SCREW-M4x20(304) | E21: 2 | F21: NOS | G21: 0.7 | H21: FOR BACK COVER FIXING | I21: =G21*E21 -> 1.4
B22: HARDWARE | C22: 10307173 | D22: SS-HEX-HEX.BOLT-M8X35(304) | E22: 2 | F22: NOS | G22: 4.35 | H22: POLE MOUNTING | I22: =G22*E22 -> 8.7
B23: HARDWARE | C23: 10303301 | D23: NYLON-CABLE-GLAND-PG9-12MM-WITH-WASHER-POWER CONNECT-BLK | E23: 1 | F23: NOS | G23: =VLOOKUP(C23,'BRP277 150 S2'!C59:G59,5,0) -> #N/A | H23: CABLE ENTRY GLAND | I23: =G23*E23 -> #N/A
B24: HARDWARE | C24: 10303182 | D24: HEAT-SHRINK-SLEEVE-WHT-Ø4 | E24: 0.1 | F24: MTR | G24: =VLOOKUP(C24,'BRP277 150 S2'!C59:G60,5,0) -> #N/A | H24: ON DC WIRES | I24: =G24*E24 -> #N/A
B25: HARDWARE | C25: 10303122 | D25: FIBRE-WASHER-M3 | E25: 10 | F25: NOS | G25: =VLOOKUP(C25,'BRP277 150 S2'!C2:F2,5,0) -> #N/A | H25: PCB FIXING | I25: =G25*E25 -> #N/A
B26: HARDWARE | C26: 10302740 | D26: SS-PAN-PH-SCREW-M3x8(304) | E26: 14 | F26: NOS | G26: =VLOOKUP(C26,'BRP277 150 S2'!C2:F3,5,0) -> #N/A | H26: LENS FIXING | I26: =G26*E26 -> #N/A
B27: HARDWARE | C27: 10302738 | D27: SS-PAN.PH-SCREW-M3X6(304) | E27: 10 | F27: NOS | G27: =VLOOKUP(C27,'BRP277 150 S2'!C2:F4,5,0) -> #N/A | H27: PCB FIXING | I27: =G27*E27 -> #N/A
B28: HARDWARE | C28: 10302735 | D28: SS-WASHER-STAR-M4(304) | E28: 1 | F28: NOS | G28: =VLOOKUP(C28,'BRP277 150 S2'!C2:F5,5,0) -> #N/A | H28: EARTHING | I28: =G28*E28 -> #N/A
B29: HARDWARE | C29: 10302450 | D29: SS-WASHER-SPRING-M4(304) | E29: 4 | F29: NOS | G29: =VLOOKUP(C29,'BRP277 150 S2'!C2:F6,5,0) -> #N/A | H29: DRIVER FIXING | I29: =G29*E29 -> #N/A
B30: HARDWARE | C30: 10302042 | D30: SS-WASHER-FLAT-M4x10mm(304) | E30: 4 | F30: NOS | G30: =VLOOKUP(C30,'BRP277 150 S2'!C2:F7,5,0) -> #N/A | H30: DRIVER FIXING | I30: =G30*E30 -> #N/A
B31: HARDWARE | C31: 10301344 | D31: CABLE-RUBBER-GK-3Cx1sq.mm-BLK(RED-BLACK-GRN/YL) IS9968:1990 1100V | E31: 0.5 | F31: MTR | G31: =VLOOKUP(C31,'BRP277 150 S2'!C2:F8,5,0) -> #N/A | H31: MAINS CABLE | I31: =G31*E31 -> #N/A
B32: HARDWARE | C32: 10301088 | D32: WIRE-PTFE-7X0.3-BLK | E32: 0.1 | F32: MTR | G32: =VLOOKUP(C32,'BRP277 150 S2'!C2:F9,5,0) -> #N/A | H32: DC WIRE | I32: =G32*E32 -> #N/A
B33: HARDWARE | C33: 10301087 | D33: WIRE-PTFE-7X0.3-RED | E33: 0.1 | F33: MTR | G33: =VLOOKUP(C33,'BRP277 150 S2'!C2:F10,5,0) -> #N/A | H33: DC WIRE | I33: =G33*E33 -> #N/A
B34: HARDWARE | C34: 10301084 | D34: WIRE-CRIMPIN CLOSE-TYPE-POWER CONNECT-2.5 SQMM | E34: 8 | F34: NOS | G34: =VLOOKUP(C34,'BRP277 150 S2'!C2:F11,5,0) -> #N/A | H34: MAINS TO DRIVER, DRIVER TO PCB | I34: =G34*E34 -> #N/A
B35: HARDWARE | C35: 10301024 | D35: WIRE-PVC-SINGLE-CORE-0.5SQ.MM-YL/GRN-WITH-EARTHING-LUG-150MM | E35: 1 | F35: NOS | G35: =VLOOKUP(C35,'BRP277 150 S2'!C2:F12,5,0) -> #N/A | H35: FOR EARTHING | I35: =G35*E35 -> #N/A
I36: =SUM(I15:I35) -> #N/A
B37: PACKING | C37: 10403110 | D37: TESTED-OK-STKR | E37: 1 | F37: NOS | G37: =VLOOKUP(C37,'BRP277 150 S2'!C2:F14,5,0) -> #N/A | H37: PACKING | I37: =G37*E37 -> #N/A
B38: PACKING | C38: 10403086 | D38: SILVER-STICKER-PAPER-NON-TEARABLE-12"X18" | E38: 0.0041 | F38: NOS | G38: =VLOOKUP(C38,'BRP277 150 S2'!C2:F15,5,0) -> #N/A | H38: PACKING | I38: =G38*E38 -> #N/A
B39: PACKING | C39: 10403075 | D39: PLAIN-PAPER-A4-SIZE | E39: 1 | F39: NOS | G39: =VLOOKUP(C39,'BRP277 150 S2'!C2:F16,5,0) -> #N/A | H39: IM SHEET | I39: =G39*E39 -> #N/A
B40: PACKING | C40: 10403018 | D40: STICKER-PAPER-12X18 INCH | E40: 0.25 | F40: NOS | G40: =VLOOKUP(C40,'BRP277 150 S2'!C2:F17,5,0) -> #N/A | H40: PACKING | I40: =G40*E40 -> #N/A
B41: PACKING | C41: 10308672 | D41: POLYBAG-10"X22"-65µ | E41: 1 | F41: NOS | G41: =VLOOKUP(C41,'BRP277 150 S2'!C2:F18,5,0) -> #N/A | H41: PACKING | I41: =G41*E41 -> #N/A
...

Sheet BRP277 150 S3
B2: 919615893873 | D2: BRP277 LED195 CW M2 SLR PSU S3
B3: 30302120 | D3: BRP277 S3 5.7K 150W
B4: Category | C4: No. | D4: Description | E4: Quantity | F4: UoM Name | G4: Unit Price | H4: Position | I4: Total
B5: HOUSING | C5: 20203439 | D5: PH-R1-STL-JA-BACK-COVER-PDC-150W-GRY-RAL-7011 | E5: 1 | F5: NOS | G5: =VLOOKUP(C5,'BRP277 150 S2'!D4:H51,5,0) -> 148.226 | H5: BACK COVER | I5: =G5*E5 -> 148.226
B6: HOUSING | C6: 20203438 | D6: PH-R1-STL-JA-HSG-PDC-150W-GRY-RAL-7011 | E6: 1 | F6: NOS | G6: =VLOOKUP(C6,'BRP277 150 S2'!D5:H52,5,0) -> 691.411 | H6: HOUSING | I6: =G6*E6 -> 691.411
B7: HOUSING | C7: 10304138 | D7: PH-R1-STL-JA-BACK COVER-PDC-150W-MOULDED-SILICON GASKET | E7: 1 | F7: NOS | G7: =VLOOKUP(C7,'BRP277 150 S2'!D6:H53,5,0) -> 23 | H7: BACK COVER GASKET | I7: =G7*E7 -> 23
B8: HOUSING | C8: 10304117 | D8: SILICON GASKET-LENS-R1-STL-BO-241-242 | E8: 1 | F8: NOS | G8: =VLOOKUP(C8,'BRP277 150 S2'!D7:H54,5,0) -> 8.5 | H8: LENS GASKET | I8: =G8*E8 -> 8.5
B9: HOUSING | C9: 10303986 | D9: LENS-R1-STL-BO241-5050-36X1-120W(5302) | E9: 1 | F9: NOS | G9: =VLOOKUP(C9,'BRP277 150 S2'!D8:H55,5,0) -> 92 | H9: LENS | I9: =G9*E9 -> 92
I10: =SUM(I5:I9) -> 963.137
B11: ELEC. | C11: 20603182 | D11: MI-DRVR-R1-STL-108V_625mA-75W-MT7939C2 (FOR 150W ST-5050) | E11: 2 | F11: NOS | G11: =VLOOKUP(C11,'BRP277 150 S2'!D10:H57,5,0) -> 252.39544 | H11: DRIVER | I11: =G11*E11 -> 504.79089
B12: ELEC. | C12: 20405423 | D12: LBRD PH R1 STL 150W 36L 5.7K-6C | E12: 1 | F12: NOS | G12: ='L2'!G30 -> 462.39 | H12: LED ENGINE | I12: =G12*E12 -> 462.39
I13: =SUM(I11:I12) -> 967.18089
B14: HARDWARE | C14: 10403049 | D14: SOLDER-BAR-ROHS-SCNG/SNG | E14: 0.0006 | F14: KGS | G14: =VLOOKUP(C14,'BRP277 150 S2'!C59:G60,5,0) -> #N/A | H14: WIRE DIPING | I14: =G14*E14 -> #N/A
B15: HARDWARE | C15: 10403047 | D15: FIBRE-GLASS-SLEEVE-H-CLASS-6MM | E15: 0.2 | F15: MTR | G15: =VLOOKUP(C15,'BRP277 150 S2'!C2:F2,5,0) -> #N/A | H15: AC DRIVER WIRE | I15: =G15*E15 -> #N/A
B16: HARDWARE | C16: 10307261 | D16: SS-PAN-COMB-WITH-WASHER-SCREW-M3X8(304) | E16: 5 | F16: NOS | G16: =VLOOKUP(C16,'BRP277 150 S2'!C2:F3,5,0) -> #N/A | H16: DRIVER FIXING + EARTHING | I16: =G16*E16 -> #N/A
B17: HARDWARE | C17: 10307175 | D17: SS-PAN-COMB-SCREW-M4X25(304) | E17: 8 | F17: NOS | G17: =VLOOKUP(C17,'BRP277 150 S2'!C2:F4,5,0) -> #N/A | H17: FOR BACK COVER FIXING | I17: =G17*E17 -> #N/A
B18: HARDWARE | C18: 10307174 | D18: SS-PAN-COMB-SCREW-M4x20(304) | E18: 2 | F18: NOS | G18: =VLOOKUP(C18,'BRP277 150 S2'!C2:F5,5,0) -> #N/A | H18: FOR BACK COVER FIXING | I18: =G18*E18 -> #N/A
B19: HARDWARE | C19: 10307173 | D19: SS-HEX-HEX.BOLT-M8X35(304) | E19: 2 | F19: NOS | G19: =VLOOKUP(C19,'BRP277 150 S2'!C2:F6,5,0) -> #N/A | H19: POLE MOUNTING | I19: =G19*E19 -> #N/A
B20: HARDWARE | C20: 10403294 | D20: THERMAL PASTE-WACKER-5TC-3073 | E20: 0.0024 | F20: KGS | G20: =VLOOKUP(C20,'BRP277 150 S2'!C2:F7,5,0) -> #N/A | H20: ON PCB | I20: =G20*E20 -> #N/A
B21: HARDWARE | C21: 10403225 | D21: SILICON SEALANT FEVI SEAL NEUTRAL PRO | E21: 0.00065 | F21: ML | G21: =VLOOKUP(C21,'BRP277 150 S2'!C2:F8,5,0) -> #N/A | H21: DC WIRE OUTPUT | I21: =G21*E21 -> #N/A
B22: HARDWARE | C22: 10303301 | D22: NYLON-CABLE-GLAND-PG9-12MM-WITH-WASHER-POWER CONNECT-BLK | E22: 1 | F22: NOS | G22: =VLOOKUP(C22,'BRP277 150 S2'!C2:F9,5,0) -> #N/A | H22: CABLE ENTRY GLAND | I22: =G22*E22 -> #N/A
B23: HARDWARE | C23: 10303182 | D23: HEAT-SHRINK-SLEEVE-WHT-Ø4 | E23: 0.1 | F23: MTR | G23: =VLOOKUP(C23,'BRP277 150 S2'!C2:F10,5,0) -> #N/A | H23: ON DC WIRES | I23: =G23*E23 -> #N/A
B24: HARDWARE | C24: 10303122 | D24: FIBRE-WASHER-M3 | E24: 10 | F24: NOS | G24: =VLOOKUP(C24,'BRP277 150 S2'!C2:F11,5,0) -> #N/A | H24: PCB FIXING | I24: =G24*E24 -> #N/A
B25: HARDWARE | C25: 10302740 | D25: SS-PAN-PH-SCREW-M3x8(304) | E25: 14 | F25: NOS | G25: =VLOOKUP(C25,'BRP277 150 S2'!C2:F12,5,0) -> #N/A | H25: LENS FIXING | I25: =G25*E25 -> #N/A
B26: HARDWARE | C26: 10302738 | D26: SS-PAN.PH-SCREW-M3X6(304) | E26: 10 | F26: NOS | G26: =VLOOKUP(C26,'BRP277 150 S2'!C2:F13,5,0) -> #N/A | H26: PCB FIXING | I26: =G26*E26 -> #N/A
B27: HARDWARE | C27: 10302735 | D27: SS-WASHER-STAR-M4(304) | E27: 1 | F27: NOS | G27: =VLOOKUP(C27,'BRP277 150 S2'!C2:F14,5,0) -> #N/A | H27: EARTHING | I27: =G27*E27 -> #N/A
B28: HARDWARE | C28: 10302450 | D28: SS-WASHER-SPRING-M4(304) | E28: 4 | F28: NOS | G28: =VLOOKUP(C28,'BRP277 150 S2'!C2:F15,5,0) -> #N/A | H28: DRIVER FIXING | I28: =G28*E28 -> #N/A
B29: HARDWARE | C29: 10302042 | D29: SS-WASHER-FLAT-M4x10mm(304) | E29: 4 | F29: NOS | G29: =VLOOKUP(C29,'BRP277 150 S2'!C2:F16,5,0) -> #N/A | H29: DRIVER FIXING | I29: =G29*E29 -> #N/A
B30: HARDWARE | C30: 10301344 | D30: CABLE-RUBBER-GK-3Cx1sq.mm-BLK(RED-BLACK-GRN/YL) IS9968:1990 1100V | E30: 0.5 | F30: MTR | G30: =VLOOKUP(C30,'BRP277 150 S2'!C2:F17,5,0) -> #N/A | H30: MAINS CABLE | I30: =G30*E30 -> #N/A
B31: HARDWARE | C31: 10301088 | D31: WIRE-PTFE-7X0.3-BLK | E31: 0.1 | F31: MTR | G31: =VLOOKUP(C31,'BRP277 150 S2'!C2:F18,5,0) -> #N/A | H31: DC WIRE | I31: =G31*E31 -> #N/A
B32: HARDWARE | C32: 10301087 | D32: WIRE-PTFE-7X0.3-RED | E32: 0.1 | F32: MTR | G32: =VLOOKUP(C32,'BRP277 150 S2'!C2:F19,5,0) -> #N/A | H32: DC WIRE | I32: =G32*E32 -> #N/A
B33: HARDWARE | C33: 10301084 | D33: WIRE-CRIMPIN CLOSE-TYPE-POWER CONNECT-2.5 SQMM | E33: 5 | F33: NOS | G33: =VLOOKUP(C33,'BRP277 150 S2'!C2:F20,5,0) -> #N/A | H33: MAINS TO DRIVER, DRIVER TO PCB | I33: =G33*E33 -> #N/A
B34: HARDWARE | C34: 10301024 | D34: WIRE-PVC-SINGLE-CORE-0.5SQ.MM-YL/GRN-WITH-EARTHING-LUG-150MM | E34: 1 | F34: NOS | G34: =VLOOKUP(C34,'BRP277 150 S2'!C2:F21,5,0) -> #N/A | H34: FOR EARTHING | I34: =G34*E34 -> #N/A
I35: =SUM(I14:I34) -> #N/A
B36: PACKING | C36: 10403110 | D36: TESTED-OK-STKR | E36: 1 | F36: NOS | G36: =VLOOKUP(C36,'BRP277 150 S2'!C2:F23,5,0) -> #N/A | H36: PACKING | I36: =G36*E36 -> #N/A
B37: PACKING | C37: 10403086 | D37: SILVER-STICKER-PAPER-NON-TEARABLE-12"X18" | E37: 0.0041 | F37: NOS | G37: =VLOOKUP(C37,'BRP277 150 S2'!C2:F24,5,0) -> #N/A | H37: PACKING | I37: =G37*E37 -> #N/A
B38: PACKING | C38: 10403075 | D38: PLAIN-PAPER-A4-SIZE | E38: 1 | F38: NOS | G38: =VLOOKUP(C38,'BRP277 150 S2'!C2:F25,5,0) -> #N/A | H38: IM SHEET | I38: =G38*E38 -> #N/A
B39: PACKING | C39: 10403018 | D39: STICKER-PAPER-12X18 INCH | E39: 0.25 | F39: NOS | G39: =VLOOKUP(C39,'BRP277 150 S2'!C2:F26,5,0) -> #N/A | H39: PACKING | I39: =G39*E39 -> #N/A
B40: PACKING | C40: 10308672 | D40: POLYBAG-10"X22"-65µ | E40: 1 | F40: NOS | G40: =VLOOKUP(C40,'BRP277 150 S2'!C2:F27,5,0) -> #N/A | H40: PACKING | I40: =G40*E40 -> #N/A
B41: PACKING | C41: 10308671 | D41: MASTER CARTON PH R1 STL 150W | E41: 1 | F41: NOS | G41: =VLOOKUP(C41,'BRP277 150 S2'!C2:F28,5,0) -> #N/A | H41: PACKING | I41: =G41*E41 -> #N/A
...

Sheet BRP277 150 SPD S3
B2: 919615893874 | D2: BRP277 LED195 CW M2 SLR PSU SPD S3
B3: 30302122 | D3: BRP277 S3 5.7K 150W SPD
B4: Category | C4: No. | D4: Description | E4: Quantity | F4: UoM Name | G4: Unit Price | H4: Position | I4: Total
B5: HOUSING | C5: 20203439 | D5: PH-R1-STL-JA-BACK-COVER-PDC-150W-GRY-RAL-7011 | E5: 1 | F5: NOS | G5: =VLOOKUP(C5,'BRP277 150 SPD S2'!C4:G51,5,0) -> 148.226 | H5: BACK COVER | I5: =G5*E5 -> 148.226
B6: HOUSING | C6: 20203438 | D6: PH-R1-STL-JA-HSG-PDC-150W-GRY-RAL-7011 | E6: 1 | F6: NOS | G6: =VLOOKUP(C6,'BRP277 150 SPD S2'!C5:G52,5,0) -> 691.411 | H6: HOUSING | I6: =G6*E6 -> 691.411
B7: HOUSING | C7: 10304138 | D7: PH-R1-STL-JA-BACK COVER-PDC-150W-MOULDED-SILICON GASKET | E7: 1 | F7: NOS | G7: =VLOOKUP(C7,'BRP277 150 SPD S2'!C6:G53,5,0) -> 23 | I7: =G7*E7 -> 23
B8: HOUSING | C8: 10304117 | D8: SILICON GASKET-LENS-R1-STL-BO-241-242 | E8: 1 | F8: NOS | G8: =VLOOKUP(C8,'BRP277 150 SPD S2'!C7:G54,5,0) -> 8.5 | H8: LENS GASKET | I8: =G8*E8 -> 8.5
B9: HOUSING | C9: 10303986 | D9: LENS-R1-STL-BO241-5050-36X1-120W(5302) | E9: 1 | F9: NOS | G9: =VLOOKUP(C9,'BRP277 150 SPD S2'!C8:G55,5,0) -> 92 | H9: LENS | I9: =G9*E9 -> 92
I10: =SUM(I5:I9) -> 963.137
B11: ELEC. | C11: 20603182 | D11: MI-DRVR-R1-STL-108V_625mA-75W-MT7939C2 (FOR 150W ST-5050) | E11: 2 | F11: NOS | G11: =VLOOKUP(C11,'BRP277 150 SPD S2'!C10:G57,5,0) -> 252.39544 | H11: DRIVER | I11: =G11*E11 -> 504.79089
B12: ELEC. | C12: 20602342 | D12: MI-SPD-R1-10KV-HS | E12: 1 | F12: NOS | G12: =SPD!H25 -> 66.243898 | H12: SPD | I12: =G12*E12 -> 66.243898
B13: ELEC. | C13: 20405423 | D13: LBRD PH R1 STL 150W 36L 5.7K-6C | E13: 1 | F13: NOS | G13: ='L2'!G30 -> 462.39 | H13: LED ENGINE | I13: =G13*E13 -> 462.39
I14: =SUM(I11:I13) -> 1033.4248
B15: HARDWARE | C15: 10403294 | D15: THERMAL PASTE-WACKER-5TC-3073 | E15: 0.0024 | F15: KGS | G15: =VLOOKUP(C15,'BRP277 150 SPD S2'!C14:G61,5,0) -> 2700 | H15: ON PCB | I15: =G15*E15 -> 6.48
B16: HARDWARE | C16: 10403225 | D16: SILICON SEALANT FEVI SEAL NEUTRAL PRO | E16: 0.00065 | F16: ML | G16: =VLOOKUP(C16,'BRP277 150 SPD S2'!C15:G62,5,0) -> 0.5 | H16: DC WIRE OUTPUT | I16: =G16*E16 -> 0.000325
B17: HARDWARE | C17: 10403049 | D17: SOLDER-BAR-ROHS-SCNG/SNG | E17: 0.0006 | F17: KGS | G17: =VLOOKUP(C17,'BRP277 150 SPD S2'!C16:G63,5,0) -> 5315 | H17: WIRE DIPING | I17: =G17*E17 -> 3.189
B18: HARDWARE | C18: 10403047 | D18: FIBRE-GLASS-SLEEVE-H-CLASS-6MM | E18: 0.2 | F18: MTR | G18: =VLOOKUP(C18,'BRP277 150 SPD S2'!C17:G64,5,0) -> 6.75 | H18: AC DRIVER WIRE | I18: =G18*E18 -> 1.35
B19: HARDWARE | C19: 10307261 | D19: SS-PAN-COMB-WITH-WASHER-SCREW-M3X8(304) | E19: 5 | F19: NOS | G19: =VLOOKUP(C19,'BRP277 150 SPD S2'!C18:G65,5,0) -> 0.35 | H19: DRIVER FIXING + EARTHING | I19: =G19*E19 -> 1.75
B20: HARDWARE | C20: 10307175 | D20: SS-PAN-COMB-SCREW-M4X25(304) | E20: 8 | F20: NOS | G20: =VLOOKUP(C20,'BRP277 150 SPD S2'!C19:G66,5,0) -> 0.9 | H20: FOR BACK COVER FIXING | I20: =G20*E20 -> 7.2
B21: HARDWARE | C21: 10307174 | D21: SS-PAN-COMB-SCREW-M4x20(304) | E21: 2 | F21: NOS | G21: =VLOOKUP(C21,'BRP277 150 SPD S2'!C20:G67,5,0) -> 0.7 | H21: FOR BACK COVER FIXING | I21: =G21*E21 -> 1.4
B22: HARDWARE | C22: 10307173 | D22: SS-HEX-HEX.BOLT-M8X35(304) | E22: 2 | F22: NOS | G22: =VLOOKUP(C22,'BRP277 150 SPD S2'!C21:G68,5,0) -> 4.35 | H22: POLE MOUNTING | I22: =G22*E22 -> 8.7
B23: HARDWARE | C23: 10303301 | D23: NYLON-CABLE-GLAND-PG9-12MM-WITH-WASHER-POWER CONNECT-BLK | E23: 1 | F23: NOS | G23: =VLOOKUP(C23,'BRP277 150 SPD S2'!C22:G69,5,0) -> #N/A | H23: CABLE ENTRY GLAND | I23: =G23*E23 -> #N/A
B24: HARDWARE | C24: 10303182 | D24: HEAT-SHRINK-SLEEVE-WHT-Ø4 | E24: 0.1 | F24: MTR | G24: =VLOOKUP(C24,'BRP277 150 SPD S2'!C23:G70,5,0) -> #N/A | H24: ON DC WIRES | I24: =G24*E24 -> #N/A
B25: HARDWARE | C25: 10303122 | D25: FIBRE-WASHER-M3 | E25: 10 | F25: NOS | G25: =VLOOKUP(C25,'BRP277 150 SPD S2'!C24:G71,5,0) -> #N/A | H25: PCB FIXING | I25: =G25*E25 -> #N/A
B26: HARDWARE | C26: 10302740 | D26: SS-PAN-PH-SCREW-M3x8(304) | E26: 14 | F26: NOS | G26: =VLOOKUP(C26,'BRP277 150 SPD S2'!C25:G72,5,0) -> #N/A | H26: LENS FIXING | I26: =G26*E26 -> #N/A
... B35: HARDWARE | C35: 10301024 | D35: WIRE-PVC-SINGLE-CORE-0.5SQ.MM-YL/GRN-WITH-EARTHING-LUG-150MM | E35: 1 | F35: NOS | G35: =VLOOKUP(C35,'BRP277 150 SPD S2'!C34:G81,5,0) -> #N/A | H35: FOR EARTHING | I35: =G35*E35 -> #N/A
I36: =SUM(I15:I35) -> #N/A
B37: PACKING | C37: 10403110 | D37: TESTED-OK-STKR | E37: 1 | F37: NOS | G37: =VLOOKUP(C37,'BRP277 150 SPD S2'!C36:G83,5,0) -> #N/A | H37: PACKING | I37: =G37*E37 -> #N/A
B38: PACKING | C38: 10403086 | D38: SILVER-STICKER-PAPER-NON-TEARABLE-12"X18" | E38: 0.0041 | F38: NOS | G38: =VLOOKUP(C38,'BRP277 150 SPD S2'!C37:G84,5,0) -> #N/A | H38: PACKING | I38: =G38*E38 -> #N/A
B39: PACKING | C39: 10403075 | D39: PLAIN-PAPER-A4-SIZE | E39: 1 | F39: NOS | G39: =VLOOKUP(C39,'BRP277 150 SPD S2'!C38:G85,5,0) -> #N/A | H39: IM SHEET | I39: =G39*E39 -> #N/A
B40: PACKING | C40: 10403018 | D40: STICKER-PAPER-12X18 INCH | E40: 0.25 | F40: NOS | G40: =VLOOKUP(C40,'BRP277 150 SPD S2'!C39:G86,5,0) -> #N/A | H40: PACKING | I40: =G40*E40 -> #N/A
B41: PACKING | C41: 10308672 | D41: POLYBAG-10"X22"-65µ | E41: 1 | F41: NOS | G41: =VLOOKUP(C41,'BRP277 150 SPD S2'!C40:G87,5,0) -> #N/A | H41: PACKING | I41: =G41*E41 -> #N/A
B42: PACKING | C42: 10308671 | D42: MASTER CARTON PH R1 STL 150W | E42: 1 | F42: NOS | G42: =VLOOKUP(C42,'BRP277 150 SPD S2'!C41:G88,5,0) -> #N/A | H42: PACKING | I42: =G42*E42 -> #N/A
B43: PACKING | C43: 10308670 | D43: PADDING-PART2-L208 X W100-PH R1 STL 150W | E43: 2 | F43: NOS | G43: =VLOOKUP(C43,'BRP277 150 SPD S2'!C42:G89,5,0) -> #N/A | H43: PACKING | I43: =G43*E43 -> #N/A
B44: PACKING | C44: 10308669 | D44: PADDING-PART1-L475 X W100-PH R1 STL 150W | E44: 2 | F44: NOS | G44: =VLOOKUP(C44,'BRP277 150 SPD S2'!C43:G90,5,0) -> #N/A | H44: PACKING | I44: =G44*E44 -> #N/A
B45: PACKING | C45: 10306734 | D45: SILVER STICKER 80X30MM | E45: 1.5 | F45: NOS | G45: =VLOOKUP(C45,'BRP277 150 SPD S2'!C44:G91,5,0) -> #N/A | H45: PACKING | I45: =G45*E45 -> #N/A
B46: PACKING | C46: 10306703 | D46: PHILIPS PACKING TAPE 2" | E46: 0.375 | F46: MTR | G46: =VLOOKUP(C46,'BRP277 150 SPD S2'!C45:G92,5,0) -> #N/A | H46: PACKING | I46: =G46*E46 -> #N/A
B47: PACKING | C47: 10306683 | D47: HEAT-SEAL-PACKING-STRAP | E47: 0.7 | F47: MTR | G47: =VLOOKUP(C47,'BRP277 150 SPD S2'!C46:G93,5,0) -> #N/A | H47: PACKING | I47: =G47*E47 -> #N/A
B48: PACKING | C48: 10306626 | D48: PLAIN STICKER 40X15MM | E48: 1 | F48: NOS | G48: =VLOOKUP(C48,'BRP277 150 SPD S2'!C47:G94,5,0) -> #N/A | H48: PACKING | I48: =G48*E48 -> #N/A
... B51: PACKING | C51: 10306207 | D51: TRANSPARENT-TAPE | E51: 0.00643 | F51: NOS | G51: =VLOOKUP(C51,'BRP277 150 SPD S2'!C50:G97,5,0) -> #N/A | H51: PACKING | I51: =G51*E51 -> #N/A
...
